<!--
	NOTES:
	Units:
		Distance: m
		Angles: rad (only option)
		Mass: kg
		Inertia: kg*m^2
-->

<robot name="ability_hand">

    <link name="upper_arm">
        <visual>
            <origin xyz="0.16 0 -0.16" rpy="0 1.5708 0"/>
            <geometry>
                <cylinder length="0.34" radius="0.03"/>
            </geometry>
        </visual>
    </link>

    <link name="lower_arm">
        <visual>
            <origin xyz="0 0 -0.16" rpy="0 0 0"/>
            <geometry>
                <cylinder length="0.34" radius="0.03"/>
            </geometry>
        </visual>
    </link>

    <joint name="elbow" type="revolute">
        <parent link="lower_arm"/>
        <child link="upper_arm"/>
        <origin xyz="0 0 -0.16" rpy="0 0 0"/>
        <axis xyz="0 1 0"/>
        <limit lower="-1.57" upper="1.57"/>
    </joint>

    <joint name="wrist_rotation" type="revolute">
        <parent link="lower_arm"/>
        <child link="wrist_link"/>
        <origin xyz="0 0 0.0" rpy="0 0 0"/>
        <axis xyz="0 0 1"/>
        <limit lower="-3.14" upper="3.14"/>
    </joint>

    <link name="wrist_link">
        <visual>
            <origin xyz="0 0 0.01" rpy="0 0 0"/>
            <geometry>
                <box size="0.05 0.02 0.02"/>
            </geometry>
        </visual>
    </link>

    <joint name="wrist_flexion" type="revolute">
        <parent link="wrist_link"/>
        <child link="base"/>
        <origin xyz="0 0 0.02" rpy="0 0 0"/>
        <axis xyz="1 0 0"/>
        <limit lower="-1.57" upper="1.57"/>
    </joint>

	<link name="base">
		<visual name="wrist_mesh">
			<origin rpy="0 0 0" xyz="0 0 0"/>
			<geometry>
				<mesh filename="models/wristmesh.STL"/>
			</geometry>
		</visual>
	</link>

	<joint name="wrist2thumb" type="fixed">
		<parent link="base"/>
		<child link="thumb_base"/>
		<origin xyz="24.0476665e-3 3.78124745e-3 32.32964923e-3" rpy="3.14148426 0.08848813 3.14036612"/>
	</joint>

	<link name="thumb_base">
		<visual name="palm_mesh">
			<origin rpy="0 0 0" xyz="0 0 0"/>
			<geometry>
				<mesh filename="models/FB_palm_ref.STL"/>
			</geometry>
		</visual>
	</link>

	<link name="index_L1">
		<visual name="index_mesh_1">
			<origin xyz="0 0 0" rpy="0 0 0"/>
			<geometry>
				<mesh filename="models/idx-F1.STL"/>
			</geometry>
		</visual>
	</link>

	<link name="index_L2">
		<visual name="index_mesh_2">
			<origin rpy="0 0 0" xyz="0 0 0"/>
			<geometry>
				<mesh filename="models/idx-F2-Lg.STL"/>
			</geometry>
		</visual>
	</link>

	<joint name="index_q1" type="revolute">
		<parent link="thumb_base"/>
		<child link="index_L1"/>
		<origin xyz="-9.49e-3 -13.04e-3 -62.95e-3" rpy="-1.982050 1.284473 -2.090591"/>
		<axis xyz="0 0 1"/>
		<limit lower="0" upper="2.0943951"/>
	</joint>

	<joint name="index_q2" type="revolute">
		<parent link="index_L1"/>
		<child link="index_L2"/>
		<origin xyz="38.472723e-3 3.257695e-3 0.000000e-3" rpy="0 0 0.084474"/>
		<axis xyz="0 0 1"/>
		<limit lower="0.0" upper="2.6586"/>
		<mimic joint="index_q1" multiplier="1.05851325" offset="0.72349796"/>
	</joint>

	<link name="index_anchor"/>
	<joint name="idx_anchor" type="fixed">
		<parent link="index_L2"/>
		<child link="index_anchor"/>
		<origin rpy="0 0 0" xyz="31.5541e-3 -10.44e-3 0.14e-3"/>
	</joint>

	<link name="middle_L1">
		<visual name="middle_mesh_1">
			<origin rpy="0 0 0" xyz="0 0 0"/>
			<geometry>
				<mesh filename="models/idx-F1.STL"/>
			</geometry>
		</visual>
	</link>

	<link name="middle_L2">
		<visual name="middle_mesh_2">
			<origin rpy="0 0 0" xyz="0 0 0"/>
			<geometry>
				<mesh filename="models/idx-F2-Lg.STL"/>
			</geometry>
		</visual>
	</link>

	<joint name="middle_q1" type="revolute">
		<parent link="thumb_base"/>
		<child link="middle_L1"/>
		<origin xyz="9.653191e-3 -15.310271e-3 -67.853949e-3" rpy="-1.860531 1.308458 -1.896217"/>
		<limit lower="0" upper="2.0943951"/>
		<axis xyz="0 0 1"/>
	</joint>

	<joint name="middle_q2" type="revolute">
		<parent link="middle_L1"/>
		<child link="middle_L2"/>
		<origin xyz="38.472723e-3 3.257695e-3 0.000000" rpy="0 0 0.084474"/>
		<axis xyz="0 0 1"/>
		<limit lower="0.0" upper="2.6586"/>
		<mimic joint="middle_q1" multiplier="1.05851325" offset="0.72349796"/>
	</joint>

	<link name="middle_anchor"/>
	<joint name="mid_anchor" type="fixed">
		<parent link="middle_L2"/>
		<child link="middle_anchor"/>
		<origin rpy="0 0 0" xyz="31.5541e-3 -10.44e-3 0.14e-3"/>
	</joint>

	<link name="ring_L1">
		<visual name="ring_mesh_1">
			<origin rpy="0 0 0" xyz="0 0 0"/>
			<geometry>
				<mesh filename="models/idx-F1.STL"/>
			</geometry>
		</visual>
	</link>

	<link name="ring_L2">
		<visual name="ring_mesh_2">
			<origin rpy="0 0 0" xyz="0 0 0"/>
			<geometry>
				<mesh filename="models/idx-F2-Lg.STL"/>
			</geometry>
		</visual>
	</link>

	<joint name="ring_q1" type="revolute">
		<parent link="thumb_base"/>
		 <child link="ring_L1"/>
		<origin xyz="29.954260e-3 -14.212492e-3 -67.286105e-3" rpy="-1.716598 1.321452 -1.675862"/>
		<limit lower="0" upper="2.0943951"/>
		<axis xyz="0 0 1"/>
	</joint>

	<joint name="ring_q2" type="revolute">
		<parent link="ring_L1"/>
		<child link="ring_L2"/>
		<origin xyz="38.472723e-3 3.257695e-3 0.000000" rpy="0 0 0.084474"/>
		<axis xyz="0 0 1"/>
		<limit lower="0.0" upper="2.6586"/>
		<mimic joint="ring_q1" multiplier="1.05851325" offset="0.72349796"/>
	</joint>

	<link name="ring_anchor"/>
	<joint name="rng_anchor" type="fixed">
		<parent link="ring_L2"/>
		<child link="ring_anchor"/>
		<origin rpy="0 0 0" xyz="31.5541e-3 -10.44e-3 0.14e-3"/>
	</joint>

	<link name="pinky_L1">
		<visual name="pinky_mesh_1">
			<origin rpy="0 0 0" xyz="0 0 0"/>
			<geometry>
				<mesh filename="models/idx-F1.STL"/>
			</geometry>
		</visual>
	</link>

	<link name="pinky_L2">
		<visual name="pinky_mesh_2">
			<origin rpy="0 0 0" xyz="0 0 0"/>
			<geometry>
				<mesh filename="models/idx-F2-Lg.STL"/>
			</geometry>
		</visual>
	</link>

	<joint name="pinky_q1" type="revolute">
		<parent link="thumb_base"/>
		<child link="pinky_L1"/>
		<origin xyz="49.521293e-3 -11.004583e-3 -63.029065e-3" rpy="-1.765110 1.322220 -1.658383"/>
		<limit lower="0" upper="2.0943951"/>
		<axis xyz="0 0 1"/>
	</joint>

	<joint name="pinky_q2" type="revolute">
		<parent link="pinky_L1"/>
		<child link="pinky_L2"/>
		<origin xyz="38.472723e-3 3.257695e-3 0.000000" rpy="0 0 0.084474"/>
		<axis xyz="0 0 1"/>
		<limit lower="0.0" upper="2.6586"/>
		<mimic joint="pinky_q1" multiplier="1.05851325" offset="0.72349796"/>
	</joint>

	<link name="pinky_anchor"/>
	<joint name="pnky_anchor" type="fixed">
		<parent link="pinky_L2"/>
		<child link="pinky_anchor"/>
		<origin rpy="0 0 0" xyz="31.5541e-3 -10.44e-3 0.14e-3"/>
	</joint>

	<link name="thumb_L1">
		<visual name="thumb_mesh_1">
			<origin rpy="0 0 0" xyz="0 0 0"/>
			<geometry>
				<mesh filename="models/thumb-F1.STL"/>
			</geometry>
		</visual>
	</link>

	<link name="thumb_L2">
		<visual name="thumb_mesh_2">
			<origin rpy="0 0 0" xyz="0 0 0"/>
			<geometry>
				<mesh filename="models/thumb-F2-left.STL"/>
			</geometry>
		</visual>
	</link>

	<joint name="thumb_q1" type="revolute">
		<parent link="thumb_base"/>
		<child link="thumb_L1"/>
		<origin xyz="0 0 0" rpy="0 0 3.330437"/>
		<axis xyz="0 0 1"/>
		<limit lower="-2.0943951" upper="0"/>
	</joint>

	<joint name="thumb_q2" type="revolute">
		<parent link="thumb_L1"/>
		<child link="thumb_L2"/>
		<origin xyz="27.8283501e-3 0 -14.7507000e-3" rpy="4.450589592585541 0 0"/>
		<axis xyz="0 0 1"/>
		<limit lower="0" upper="2.0943951"/>
	</joint>

	<link name="thumb_anchor"/>
	<joint name="thmb_anchor" type="fixed">
		<parent link="thumb_L2"/>
		<child link="thumb_anchor"/>
		<origin rpy="0 0 0" xyz="52.0012259e-3 28.0086971e-3 -.884835778e-3"/>
	</joint>

</robot>